const x = 3

try {
    x = 2
}catch(err){
    console.log(`erro: ${err}`)
}